Traceback (most recent call last):
  File "/usr/local/lib/python3.10/dist-packages/jupyter_cache/executors/utils.py", line 58, in single_nb_execution
    executenb(
  File "/usr/local/lib/python3.10/dist-packages/nbclient/client.py", line 1305, in execute
    return NotebookClient(nb=nb, resources=resources, km=km, **kwargs).execute()
  File "/usr/local/lib/python3.10/dist-packages/jupyter_core/utils/__init__.py", line 166, in wrapped
    return loop.run_until_complete(inner)
  File "/usr/lib/python3.10/asyncio/base_events.py", line 649, in run_until_complete
    return future.result()
  File "/usr/local/lib/python3.10/dist-packages/nbclient/client.py", line 705, in async_execute
    await self.async_execute_cell(
  File "/usr/local/lib/python3.10/dist-packages/nbclient/client.py", line 1058, in async_execute_cell
    await self._check_raise_for_error(cell, cell_index, exec_reply)
  File "/usr/local/lib/python3.10/dist-packages/nbclient/client.py", line 914, in _check_raise_for_error
    raise CellExecutionError.from_cell_and_msg(cell, exec_reply_content)
nbclient.exceptions.CellExecutionError: An error occurred while executing the following cell:
------------------
X = df_copy[['sepal_length', 'sepal_width', 'petal_length', 'petal_width']]
y = df_copy['species']
------------------


[0;31m[0m
[0;31mKeyError[0mTraceback (most recent call last)
[0;32m<ipython-input-7-da965be4fcfb>[0m in [0;36m<cell line: 1>[0;34m()[0m
[0;32m----> 1[0;31m [0mX[0m [0;34m=[0m [0mdf_copy[0m[0;34m[[0m[0;34m[[0m[0;34m'sepal_length'[0m[0;34m,[0m [0;34m'sepal_width'[0m[0;34m,[0m [0;34m'petal_length'[0m[0;34m,[0m [0;34m'petal_width'[0m[0;34m][0m[0;34m][0m[0;34m[0m[0;34m[0m[0m
[0m[1;32m      2[0m [0my[0m [0;34m=[0m [0mdf_copy[0m[0;34m[[0m[0;34m'species'[0m[0;34m][0m[0;34m[0m[0;34m[0m[0m

[0;32m/usr/local/lib/python3.10/dist-packages/pandas/core/frame.py[0m in [0;36m__getitem__[0;34m(self, key)[0m
[1;32m   3811[0m             [0;32mif[0m [0mis_iterator[0m[0;34m([0m[0mkey[0m[0;34m)[0m[0;34m:[0m[0;34m[0m[0;34m[0m[0m
[1;32m   3812[0m                 [0mkey[0m [0;34m=[0m [0mlist[0m[0;34m([0m[0mkey[0m[0;34m)[0m[0;34m[0m[0;34m[0m[0m
[0;32m-> 3813[0;31m             [0mindexer[0m [0;34m=[0m [0mself[0m[0;34m.[0m[0mcolumns[0m[0;34m.[0m[0m_get_indexer_strict[0m[0;34m([0m[0mkey[0m[0;34m,[0m [0;34m"columns"[0m[0;34m)[0m[0;34m[[0m[0;36m1[0m[0;34m][0m[0;34m[0m[0;34m[0m[0m
[0m[1;32m   3814[0m [0;34m[0m[0m
[1;32m   3815[0m         [0;31m# take() does not accept boolean indexers[0m[0;34m[0m[0;34m[0m[0m

[0;32m/usr/local/lib/python3.10/dist-packages/pandas/core/indexes/base.py[0m in [0;36m_get_indexer_strict[0;34m(self, key, axis_name)[0m
[1;32m   6068[0m             [0mkeyarr[0m[0;34m,[0m [0mindexer[0m[0;34m,[0m [0mnew_indexer[0m [0;34m=[0m [0mself[0m[0;34m.[0m[0m_reindex_non_unique[0m[0;34m([0m[0mkeyarr[0m[0;34m)[0m[0;34m[0m[0;34m[0m[0m
[1;32m   6069[0m [0;34m[0m[0m
[0;32m-> 6070[0;31m         [0mself[0m[0;34m.[0m[0m_raise_if_missing[0m[0;34m([0m[0mkeyarr[0m[0;34m,[0m [0mindexer[0m[0;34m,[0m [0maxis_name[0m[0;34m)[0m[0;34m[0m[0;34m[0m[0m
[0m[1;32m   6071[0m [0;34m[0m[0m
[1;32m   6072[0m         [0mkeyarr[0m [0;34m=[0m [0mself[0m[0;34m.[0m[0mtake[0m[0;34m([0m[0mindexer[0m[0;34m)[0m[0;34m[0m[0;34m[0m[0m

[0;32m/usr/local/lib/python3.10/dist-packages/pandas/core/indexes/base.py[0m in [0;36m_raise_if_missing[0;34m(self, key, indexer, axis_name)[0m
[1;32m   6128[0m                 [0;32mif[0m [0muse_interval_msg[0m[0;34m:[0m[0;34m[0m[0;34m[0m[0m
[1;32m   6129[0m                     [0mkey[0m [0;34m=[0m [0mlist[0m[0;34m([0m[0mkey[0m[0;34m)[0m[0;34m[0m[0;34m[0m[0m
[0;32m-> 6130[0;31m                 [0;32mraise[0m [0mKeyError[0m[0;34m([0m[0;34mf"None of [{key}] are in the [{axis_name}]"[0m[0;34m)[0m[0;34m[0m[0;34m[0m[0m
[0m[1;32m   6131[0m [0;34m[0m[0m
[1;32m   6132[0m             [0mnot_found[0m [0;34m=[0m [0mlist[0m[0;34m([0m[0mensure_index[0m[0;34m([0m[0mkey[0m[0;34m)[0m[0;34m[[0m[0mmissing_mask[0m[0;34m.[0m[0mnonzero[0m[0;34m([0m[0;34m)[0m[0;34m[[0m[0;36m0[0m[0;34m][0m[0;34m][0m[0;34m.[0m[0munique[0m[0;34m([0m[0;34m)[0m[0;34m)[0m[0;34m[0m[0;34m[0m[0m

[0;31mKeyError[0m: "None of [Index(['sepal_length', 'sepal_width', 'petal_length', 'petal_width'], dtype='object')] are in the [columns]"

